Workbook
Name Agro: Agro!$B$8
Name Simulação_deCarteiras: 'Simulador de Aportes (R$)'!$B$5
Name Simulação_deCarteiras: 'Simulador de Carteiras (R$)'!$B$5
Name Simulação_deCarteiras: 'Simulador de Carteiras (%)'!$B$5
Name SimulaçãoFin: 'Simulador de Carteiras (%)'!$B$5

Sheet Menu
D5: Indicadores de Fundos Listados (FIIs, Fiagros e FI-Infras) | F5: Comparativo Setorial | H5: Indicadores de Fiagros | J5: Indicadores de FI-Infras | L5: Recebíveis | N5: Galpões Logísticos | P5: Lajes Corporativas
F8: Shopping Centers | H8: Híbridos | J8: Educacional | L8: Hospital | N8: Residencial | P8: Fundo de Fundos
B10: Stock Guide de Fundos Listados
F11: Hedge Funds | H11: Agronegócio | J11: Desenvolvimento | L11: Hotel | N11: Renda Urbana | P11: Outros
D16: Simulador de Carteira (%) | F16: Simulador de Carteira (R$) | H16: Simulador de Aporte (R$)
B19: Daniel Marinelli
B20: BTG Pactual - Equity Research
B22: Matheus Oliveira
B23: BTG Pactual - Equity Research
B25: Frederico Khouri
B26: BTG Pactual - Credit Research
D27: Acesse nosso site | F27: Glossário | H27: Disclaimer
B28: Luis Gonçalves
B29: BTG Pactual - Credit Research
B33: • Filtramos os fundos que possuem um volume de negociação, em média, acima de R$ 30 mil por dia.

Sheet Stock Guide
D2: Menu | I2: Menu
U3: Retorno
E4: Características | H4: Part. IFIX | I4: Volume de Negociação | J4: Fechamento | K4: Máximo | M4: Valor de Mercado | N4: Valor Patrimonial | O4: P/VPA | Q4: Dividend Yield (% ao ano) | U4: No Mês | V4: No Ano | W4: LTM | X4: Análises
B5: Código | C5: CNPJ | D5: Nome | E5: Gestor | F5: Administrador | G5: Segmento | H5: % | I5: Média - 3 Meses (R$) | J5: R$ | K5: R$ | L5: % | M5: R$ | N5: R$ | O5: Atual | P5: 2025 | Q5: LTM | R5: Anualizado | S5: Última Dist. (%) | T5: Div. do Mês (R$) | U5: % | V5: % | W5: % | X5: -
B6: AAZQ11 | C6: 44625826000111 | D6: Az Quest Sole Fiagro-FII | E6: AZ Quest | F6: XP Investimentos | G6: FIAgro - FII | H6: - | I6: 383825.05 | J6: 6.31 | K6: 8.0364233 | L6: 0.78517517 | M6: 1.5167526e+08 | N6: 2.0764849e+08 | O6: 0.73044239 | P6: 1.0183375 | Q6: 0.20166403 | R6: 0.17115689 | S6: 0.014263074 | T6: 0.09 | U6: -0.049698795 | V6: -0.20007913 | W6: -0.0079482424 | X6: =IF(OR(B6="",G6="FI-Infra"),"",HYPERLINK("https://content.btgpactual.com/research/ativo/https://content.btgpactual.com/research/ativo/"&B6,"Link")) -> Link
B7: ABCP11 | C7: 1201140000190 | D7: Grand Plaza Shopping FII | E7: Rio Bravo | F7: Rio Bravo | G7: Shopping Center | H7: 0 | I7: 56028.05 | J7: 74 | K7: 81.165236 | L7: 0.91172038 | M7: 348472068 | N7: 5.2143601e+08 | O7: 0.66829306 | P7: 0.71951994 | Q7: 0.095945946 | R7: 0.089189189 | S7: 0.0074324324 | T7: 0.55 | U7: 0.012035011 | V7: -0.021690115 | W7: -0.040048699 | X7: =IF(OR(B7="",G7="FI-Infra"),"",HYPERLINK("https://content.btgpactual.com/research/ativo/https://content.btgpactual.com/research/ativo/"&B7,"Link")) -> Link
B8: ADSH11 | C8: 63375304000153 | D8: - | E8: Capitânia | F8: Oliveira Trust | G8: Shopping Center | H8: 0 | I8: 17169251 | J8: 10.84 | K8: 0 | M8: 5.0917817e+08 | N8: 4.6846971e+08 | O8: 1.0868967 | P8: - | Q8: - | R8: 0.022140221 | S8: 0.0018450185 | T8: 0.02 | U8: 0.0055504446 | V8: - | W8: - | X8: =IF(OR(B8="",G8="FI-Infra"),"",HYPERLINK("https://content.btgpactual.com/research/ativo/https://content.btgpactual.com/research/ativo/"&B8,"Link")) -> Link
B9: AFHF11 | C9: 60077386000161 | D9: - | E9: AF Invest | F9: Banco Daycoval | G9: Hedge Fund | H9: 0 | I9: 89403.425 | J9: 10 | K9: 10.02 | L9: 0.99800399 | M9: 50000000 | N9: 51025266 | O9: 0.9799067 | P9: 0.97724501 | Q9: 0.1615 | R9: 0.144 | S9: 0.012 | T9: 0.12 | U9: 0.011134614 | V9: 0.1147934 | W9: 0.17553394 | X9: =IF(OR(B9="",G9="FI-Infra"),"",HYPERLINK("https://content.btgpactual.com/research/ativo/https://content.btgpactual.com/research/ativo/"&B9,"Link")) -> Link
B10: AFHI11 | C10: 36642293000158 | D10: AF Invest CRI Recebíveis FII | E10: AF Invest | F10: BTG Pactual | G10: Recebível | H10: 0.00354 | I10: 681268.43 | J10: 93.15 | K10: 93.95284 | L10: 0.99145486 | M10: 4.9265274e+08 | N10: 5.0353984e+08 | O10: 0.97837887 | P10: 1.0130099 | Q10: 0.1294686 | R10: 0.12882448 | S10: 0.010735373 | T10: 1 | U10: -0.002619798 | V10: 0.058189061 | W10: 0.16238602 | X10: =IF(OR(B10="",G10="FI-Infra"),"",HYPERLINK("https://content.btgpactual.com/research/ativo/https://content.btgpactual.com/research/ativo/"&B10,"Link")) -> Link
B11: AGRX11 | C11: 43951911000107 | D11: Exes Araguaia Fiagro-FII | E11: Éxes Gestora de Recursos | F11: Genial | G11: FIAgro - FII | H11: - | I11: 274096.55 | J11: 7.81 | K11: 8.5693506 | L11: 0.91138761 | M11: - | N11: 1.8898605e+08 | O11: - | P11: - | Q11: 0.18693982 | R11: 0.184379 | S11: 0.015364917 | T11: 0.12 | U11: -0.0090326633 | V11: 0.041360238 | W11: 0.16925284 | X11: =IF(OR(B11="",G11="FI-Infra"),"",HYPERLINK("https://content.btgpactual.com/research/ativo/https://content.btgpactual.com/research/ativo/"&B11,"Link")) -> Link
B12: AIEC11 | C12: 35765826000126 | D12: Autonomy Edifícios Corporativos FII | E12: - | F12: MAF | G12: Laje Corporativa | H12: 0 | I12: 293365.47 | J12: 64.6 | K12: 64.6 | L12: 1 | M12: 3.1169416e+08 | N12: 3.6570645e+08 | O12: 0.85230697 | P12: 0.68757596 | Q12: 0.064396285 | R12: 0.070588235 | S12: 0.0058823529 | T12: 0.38 | U12: 0.065654899 | V12: 0.27851466 | W12: 0.50746662 | X12: =IF(OR(B12="",G12="FI-Infra"),"",HYPERLINK("https://content.btgpactual.com/research/ativo/https://content.btgpactual.com/research/ativo/"&B12,"Link")) -> Link
B13: AJFI11 | C13: 51472985000199 | D13: AJ Malls FII | E13: Capitânia | F13: XP Investimentos | G13: Shopping Center | H13: 0 | I13: 934554.58 | J13: 8.3 | K13: 8.3822129 | L13: 0.99019198 | M13: 2.7909562e+08 | N13: 3.5154771e+08 | O13: 0.79390537 | P13: 0.72528443 | Q13: 0.072650602 | R13: 0.083855422 | S13: 0.0069879518 | T13: 0.058 | U13: 0.023157678 | V13: 0.083783368 | W13: 0.19234408 | X13: =IF(OR(B13="",G13="FI-Infra"),"",HYPERLINK("https://content.btgpactual.com/research/ativo/https://content.btgpactual.com/research/ativo/"&B13,"Link")) -> Link
B14: ALZC11 | C14: 40011324000140 | D14: Alianza Crédito Imobiliário FII | E14: Alianza Investimentos | F14: BTG Pactual | G14: Recebível | H14: 0 | I14: 225645.14 | J14: 7.47 | K14: 7.47 | L14: 1 | M14: 1.8189573e+08 | N14: 2.2282429e+08 | O14: 0.81631911 | P14: 0.82419992 | Q14: 0.16291834 | R14: 0.16064257 | S14: 0.013386881 | T14: 0.1 | U14: 0.019347241 | V14: 0.072841592 | W14: 0.16597329 | X14: =IF(OR(B14="",G14="FI-Infra"),"",HYPERLINK("https://content.btgpactual.com/research/ativo/https://content.btgpactual.com/research/ativo/"&B14,"Link")) -> Link
B15: ALZR11 | C15: 28737771000185 | D15: Alianza Trust Renda Imobiliária FII | E15: Alianza Investimentos | F15: BTG Pactual | G15: Híbrido | H15: 0.01161 | I15: 3349769.8 | J15: 9.97 | K15: 10.348441 | L15: 0.96343017 | M15: 1639511675 | N15: 1.7730147e+09 | O15: 0.92470283 | P15: 1.0121543 | Q15: 0.10076229 | R15: 0.10110331 | S15: 0.0084252758 | T15: 0.084 | U15: 0.0026472876 | V15: -0.011066424 | W15: 0.099154964 | X15: =IF(OR(B15="",G15="FI-Infra"),"",HYPERLINK("https://content.btgpactual.com/research/ativo/https://content.btgpactual.com/research/ativo/"&B15,"Link")) -> Link
B16: APXM11 | C16: 43010485000107 | D16: Apex Malls FII | E16: Carbyne Investimentos | F16: BTG Pactual | G16: Shopping Center | H16: 0 | I16: 106699.62 | J16: 39.5 | K16: 85.704342 | L16: 0.4608868 | M16: 111751109 | N16: 3.5465979e+08 | O16: 0.31509383 | P16: 0.70719826 | Q16: 0.11956441 | R16: 0.08323839 | S16: 0.0069365325 | T16: 0.27399303 | U16: -0.37285088 | V16: -0.5391132 | W16: -0.50857475 | X16: =IF(OR(B16="",G16="FI-Infra"),"",HYPERLINK("https://content.btgpactual.com/research/ativo/https://content.btgpactual.com/research/ativo/"&B16,"Link")) -> Link
B17: ARRI11 | C17: 32006821000121 | D17: Open K Ativos e Recebíveis Imobiliários FII | E17: Open Kapital | F17: Oliveira Trust | G17: Recebível | H17: 0 | I17: 176289.94 | J17: 4.64 | K17: 6.5043155 | L17: 0.71337253 | M17: 96173155 | N17: 1.7512428e+08 | O17: 0.54917088 | P17: 0.808837 | Q17: 0.2112069 | R17: 0.18103448 | S17: 0.015086207 | T17: 0.07 | U17: 0.01754386 | V17: -0.24690251 | W17: -0.18560782 | X17: =IF(OR(B17="",G17="FI-Infra"),"",HYPERLINK("https://content.btgpactual.com/research/ativo/https://content.btgpactual.com/research/ativo/"&B17,"Link")) -> Link
B18: ARTE11 | C18: 53193237000100 | D18: - | E18: - | F18: BTG Pactual | G18: Recebível | H18: 0 | I18: 67940.721 | J18: 7.15 | K18: 0 | M18: 67922447 | N18: 96287693 | O18: 0.70541152 | P18: - | Q18: - | R18: 0.18461538 | S18: 0.015384615 | T18: 0.11 | U18: -0.011385885 | V18: - | W18: - | X18: =IF(OR(B18="",G18="FI-Infra"),"",HYPERLINK("https://content.btgpactual.com/research/ativo/https://content.btgpactual.com/research/ativo/"&B18,"Link")) -> Link
B19: ARXD11 | C19: 44527494000132 | D19: ARX Dover Recebíveis FII | E19: ARX Investimentos | F19: Hedge | G19: Recebível | H19: 0 | I19: 63631.76 | J19: 7.58 | K19: 8.2884391 | L19: 0.91452684 | M19: 65596797 | N19: 78715004 | O19: 0.83334553 | P19: 0.84061424 | Q19: 0.14577836 | R19: 0.14248021 | S19: 0.011873351 | T19: 0.09 | U19: -0.023195876 | V19: 0.07392603 | W19: 0.17499247 | X19: =IF(OR(B19="",G19="FI-Infra"),"",HYPERLINK("https://content.btgpactual.com/research/ativo/https://content.btgpactual.com/research/ativo/"&B19,"Link")) -> Link
B20: AZPL11 | C20: 51890054000100 | D20: Az Quest Panorama Logística FII | E20: - | F20: Banco Daycoval | G20: Galpão Logístico | H20: 0.00208 | I20: 663731.47 | J20: 7.35 | K20: 7.5173945 | L20: 0.97773238 | M20: 3.0813176e+08 | N20: 3.60754e+08 | O20: 0.85413263 | P20: 0.89178953 | Q20: 0.12380952 | R20: 0.12244898 | S20: 0.010204082 | T20: 0.075 | U20: -0.0033898305 | V20: 0.030628095 | W20: 0.0908164 | X20: =IF(OR(B20="",G20="FI-Infra"),"",HYPERLINK("https://content.btgpactual.com/research/ativo/https://content.btgpactual.com/research/ativo/"&B20,"Link")) -> Link
B21: BBFO11 | C21: 37180091000102 | D21: BB Fundo de Fundos Imobiliários FII | E21: BB Asset Management | F21: BB Asset Management | G21: Fundo de Fundos | H21: 0 | I21: 405080.61 | J21: 66.1 | K21: 70.094947 | L21: 0.94300663 | M21: 264657790 | N21: 2.8134132e+08 | O21: 0.94070005 | P21: 0.83033553 | Q21: 0.15173979 | R21: 0.17246596 | S21: 0.014372163 | T21: 0.95 | U21: -0.025504939 | V21: 0.13847616 | W21: 0.23566117 | X21: =IF(OR(B21="",G21="FI-Infra"),"",HYPERLINK("https://content.btgpactual.com/research/ativo/https://content.btgpactual.com/research/ativo/"&B21,"Link")) -> Link
B22: BBGO11 | C22: 42592257000120 | D22: BB Fundo de Investimento de Crédito Fiagro-FII | E22: BB Asset Management | F22: BB Asset Management | G22: FIAgro - FII | H22: - | I22: 322826.9 | J22: 61.74 | K22: 74.979858 | L22: 0.82342114 | M22: 2.4727883e+08 | N22: 3.7340021e+08 | O22: 0.66223537 | P22: 0.83319821 | Q22: 0.17039197 | R22: 0.15549077 | S22: 0.012957564 | T22: 0.8 | U22: -0.045602102 | V22: -0.022997524 | W22: 0.10553178 | X22: =IF(OR(B22="",G22="FI-Infra"),"",HYPERLINK("https://content.btgpactual.com/research/ativo/https://content.btgpactual.com/research/ativo/"&B22,"Link")) -> Link
B23: BBIG11 | C23: 54375187000137 | D23: BB Premium Malls FII | E23: BB Asset Management | F23: BB Asset Management | G23: Shopping Center | H23: 0.00309 | I23: 1108337.9 | J23: 4.61 | K23: 7.2890515 | L23: 0.6324554 | M23: 4.5694778e+08 | N23: 9.7073328e+08 | O23: 0.47072434 | P23: 0.73113652 | Q23: 0.17787419 | R23: 0.078091106 | S23: 0.0065075922 | T23: 0.03 | U23: -0.15722121 | V23: -0.31901698 | W23: -0.25527842 | X23: =IF(OR(B23="",G23="FI-Infra"),"",HYPERLINK("https://content.btgpactual.com/research/ativo/https://content.btgpactual.com/research/ativo/"&B23,"Link")) -> Link
B24: BBRC11 | C24: 12681340000104 | D24: BB Renda Corporativa FII | E24: Tivio Capital | F24: Bem | G24: Agência Bancária | H24: 0 | I24: 70678.016 | J24: 102.06 | K24: 103.94305 | L24: 0.98188379 | M24: 162275400 | N24: 1.6472335e+08 | O24: 0.98513902 | P24: 0.96302072 | Q24: 0.14452283 | R24: 0.12345679 | S24: 0.010288066 | T24: 1.05 | U24: -0.01162115 | V24: 0.097308533 | W24: 0.18693957 | X24: =IF(OR(B24="",G24="FI-Infra"),"",HYPERLINK("https://content.btgpactual.com/research/ativo/https://content.btgpactual.com/research/ativo/"&B24,"Link")) -> Link
B25: BCIA11 | C25: 20216935000117 | D25: Bradesco Carteira Imobiliária Ativa FII | E25: - | F25: - | G25: Fundo de Fundos | H25: 0.00218 | I25: 360065.12 | J25: 86.8 | K25: 92.977744 | L25: 0.93355674 | M25: 3.228125e+08 | N25: 3.6329199e+08 | O25: 0.88857588 | P25: 0.85258465 | Q25: 0.11970046 | R25: 0.11889401 | S25: 0.0099078341 | T25: 0.86 | U25: -0.010938924 | V25: 0.054525614 | W25: 0.19145502 | X25: =IF(OR(B25="",G25="FI-Infra"),"",HYPERLINK("https://content.btgpactual.com/research/ativo/https://content.btgpactual.com/research/ativo/"&B25,"Link")) -> Link
B26: BCRI11 | C26: 22219335000138 | D26: Banestes Recebíveis Imobiliários FII | E26: Banestes DTVM | F26: BRL Trust | G26: Recebível | H26: 0.00244 | I26: 346838.47 | J26: 57.5 | K26: 65.541663 | L26: 0.87730456 | M26: 3.598277e+08 | N26: 5.3406451e+08 | O26: 0.67375325 | P26: 0.80474643 | Q26: 0.16713043 | R26: 0.16695652 | S26: 0.013913043 | T26: 0.8 | U26: -0.026908106 | V26: -0.082624692 | W26: 0.048343213 | X26: =IF(OR(B26="",G26="FI-Infra"),"",HYPERLINK("https://content.btgpactual.com/research/ativo/https://content.btgpactual.com/research/ativo/"&B26,"Link")) -> Link
B27: BDIF11 | C27: 40502607000194 | D27: BTG Pactual Dívida Infra FIC FI-Infra | E27: BTG Pactual | F27: BTG Pactual | G27: FI-Infra | H27: - | I27: 2152614.5 | J27: 68.34 | K27: 73.712369 | L27: 0.92711712 | M27: 1.2386611e+09 | N27: 1.4272615e+09 | O27: 0.86785855 | P27: - | Q27: 0.13974246 | R27: 0.14925373 | S27: 0.012437811 | T27: 0.85 | U27: -0.013921388 | V27: 0.026322057 | W27: 0.07456221 | X27: =IF(OR(B27="",G27="FI-Infra"),"",HYPERLINK("https://content.btgpactual.com/research/ativo/https://content.btgpactual.com/research/ativo/"&B27,"Link"))
B28: BIDB11 | C28: 42294971000131 | D28: Inter Infra FIC FI - Infra listado | E28: Inter | F28: Inter | G28: FI-Infra | H28: - | I28: 201660.78 | J28: 74 | K28: 78.148844 | L28: 0.946911 | M28: 1.8468646e+08 | N28: 1.9481402e+08 | O28: 0.94801424 | P28: - | Q28: 0.16216216 | R28: 0.16216216 | S28: 0.013513514 | T28: 1 | U28: -0.043927649 | V28: 0.021997345 | W28: 0.10698394 | X28: =IF(OR(B28="",G28="FI-Infra"),"",HYPERLINK("https://content.btgpactual.com/research/ativo/https://content.btgpactual.com/research/ativo/"&B28,"Link"))
B29: BINC11 | C29: 55239865000105 | D29: Bradesco FIC FI Renda Fixa Infra CDI | E29: Bradesco Asset Management | F29: Banco Bradesco | G29: FI-Infra | H29: - | I29: 785178.16 | J29: 102.9 | K29: 105.99 | L29: 0.97084631 | M29: 1.1953158e+09 | N29: 1.1703078e+09 | O29: 1.0213688 | P29: - | Q29: 0.17006803 | R29: 0.17492711 | S29: 0.014577259 | T29: 1.5 | U29: -0.010957324 | V29: 0.13091287 | W29: 0.26665811 | X29: =IF(OR(B29="",G29="FI-Infra"),"",HYPERLINK("https://content.btgpactual.com/research/ativo/https://content.btgpactual.com/research/ativo/"&B29,"Link"))
B30: BLCA11 | C30: 41076748000155 | D30: Catuaí VBI Triple A FII | E30: Patria | F30: BTG Pactual | G30: Laje Corporativa | H30: 0 | I30: 82219.908 | J30: 102.52 | K30: 104.99 | L30: 0.97647395 | M30: 164032000 | N30: 1.9902566e+08 | O30: 0.82417514 | P30: 0.73769599 | Q30: 0.099492782 | R30: 0.52672649 | S30: 0.043893874 | T30: 4.5 | U30: 0.14381806 | V30: 0.17240821 | W30: 0.21023195 | X30: =IF(OR(B30="",G30="FI-Infra"),"",HYPERLINK("https://content.btgpactual.com/research/ativo/https://content.btgpactual.com/research/ativo/"&B30,"Link")) -> Link
B31: BLMG11 | C31: 34081637000171 | D31: Bluemacaw Logística FII | E31: Bluemacaw | F31: Vórtx | G31: Galpão Logístico | H31: 0 | I31: 273254.03 | J31: 30.69 | K31: 34.309673 | L31: 0.89449993 | M31: 142555050 | N31: 2.1348918e+08 | O31: 0.667739 | P31: 0.74207244 | Q31: 0.1517074 | R31: 0.15249267 | S31: 0.012707722 | T31: 0.39 | U31: -0.10446835 | V31: -0.026455113 | W31: 0.11035084 | X31: =IF(OR(B31="",G31="FI-Infra"),"",HYPERLINK("https://content.btgpactual.com/research/ativo/https://content.btgpactual.com/research/ativo/"&B31,"Link")) -> Link
B32: BNFS11 | C32: 15570431000160 | D32: Banrisul Novas Fronteiras FII | E32: Oliveira Trust | F32: Oliveira Trust | G32: Agência Bancária | H32: 0 | I32: 33422.893 | J32: 39.3 | K32: 70.710092 | L32: 0.55579054 | M32: 27510000 | N32: 48056176 | O32: 0.57245504 | P32: 0.94645405 | Q32: 0.20992366 | R32: 0.15267176 | S32: 0.012722646 | T32: 0.5 | U32: -0.0020314881 | V32: -0.42548165 | W32: -0.36419539 | X32: =IF(OR(B32="",G32="FI-Infra"),"",HYPERLINK("https://content.btgpactual.com/research/ativo/https://content.btgpactual.com/research/ativo/"&B32,"Link")) -> Link
B33: BODB11 | C33: 41771670000199 | D33: Bocaina FIC FI-Infra | E33: Bocaina Capital | F33: BTG Pactual | G33: FI-Infra | H33: - | I33: 921585.67 | J33: 7.13 | K33: 7.7079948 | L33: 0.9250136 | M33: 4.6257371e+08 | N33: 5.1896933e+08 | O33: 0.8913315 | P33: - | Q33: 0.1598878 | R33: 0.15147265 | S33: 0.012622721 | T33: 0.09 | U33: -0.054376658 | V33: -0.01110907 | W33: 0.14308479 | X33: =IF(OR(B33="",G33="FI-Infra"),"",HYPERLINK("https://content.btgpactual.com/research/ativo/https://content.btgpactual.com/research/ativo/"&B33,"Link"))
B34: BPML11 | C34: 33046142000149 | D34: BTG Pactual Shoppings FII | E34: BTG Pactual | F34: BTG Pactual | G34: Shopping Center | H34: 0.00417 | I34: 831205.56 | J34: 82.82 | K34: 93.957069 | L34: 0.8814664 | M34: 6.1632532e+08 | N34: 8.889312e+08 | O34: 0.69333298 | P34: 0.68751429 | Q34: 0.13330113 | R34: 0.13330113 | S34: 0.011108428 | T34: 0.92 | U34: -0.0096524074 | V34: 0.056117074 | W34: 0.20957866 | X34: =IF(OR(B34="",G34="FI-Infra"),"",HYPERLINK("https://content.btgpactual.com/research/ativo/https://content.btgpactual.com/research/ativo/"&B34,"Link")) -> Link
B35: BRCO11 | C35: 20748515000181 | D35: Bresco Logística FII | E35: - | F35: Oliveira Trust | G35: Galpão Logístico | H35: 0.01363 | I35: 5135986.4 | J35: 111.84 | K35: 118.10233 | L35: 0.94697537 | M35: 2.0155025e+09 | N35: 2.0701321e+09 | O35: 0.97361058 | P35: 1.0053638 | Q35: 0.097639485 | R35: 0.097639485 | S35: 0.0081366237 | T35: 0.91 | U35: -0.019291477 | V35: 0.010814626 | W35: 0.12894551 | X35: =IF(OR(B35="",G35="FI-Infra"),"",HYPERLINK("https://content.btgpactual.com/research/ativo/https://content.btgpactual.com/research/ativo/"&B35,"Link")) -> Link
B36: BRCR11 | C36: 8924783000101 | D36: BTG Pactual Corporate Offices FII | E36: BTG Pactual | F36: BTG Pactual | G36: Laje Corporativa | H36: 0.00706 | I36: 1254897.8 | J36: 39.19 | K36: 47.523353 | L36: 0.82464719 | M36: 1.0439511e+09 | N36: 2.1579131e+09 | O36: 0.48377811 | P36: 0.53699018 | Q36: 0.12554223 | R36: 0.12554223 | S36: 0.010461853 | T36: 0.41 | U36: -0.018103263 | V36: -0.082991445 | W36: 0.084784476 | X36: =IF(OR(B36="",G36="FI-Infra"),"",HYPERLINK("https://content.btgpactual.com/research/ativo/https://content.btgpactual.com/research/ativo/"&B36,"Link")) -> Link
B37: BRFT11 | C37: 52512069000106 | D37: Bradesco Farmtech Fiagro-FIDC | E37: Bradesco Asset Management | F37: Oliveira Trust | G37: FIAgro - FIDC | H37: - | I37: 133161.37 | J37: 65 | K37: 87.439805 | L37: 0.74336854 | M37: - | O37: - | P37: - | Q37: 0.20169231 | R37: - | S37: - | T37: - | U37: -0.14453516 | V37: -0.16017564 | W37: -0.10927219 | X37: =IF(OR(B37="",G37="FI-Infra"),"",HYPERLINK("https://content.btgpactual.com/research/ativo/https://content.btgpactual.com/research/ativo/"&B37,"Link")) -> Link
B38: BROF11 | C38: 48978859000104 | D38: BRPR Corporate Offices FII | E38: BGR Asset | F38: BTG Pactual | G38: Laje Corporativa | H38: 0.00458 | I38: 760023.75 | J38: 58.3 | K38: 62.957466 | L38: 0.92602202 | M38: 6.7691034e+08 | N38: 1.259238e+09 | O38: 0.53755553 | P38: 0.51209534 | Q38: 0.11132075 | R38: 0.11526587 | S38: 0.0096054889 | T38: 0.56 | U38: -0.019307355 | V38: 0.11714695 | W38: 0.20502185 | X38: =IF(OR(B38="",G38="FI-Infra"),"",HYPERLINK("https://content.btgpactual.com/research/ativo/https://content.btgpactual.com/research/ativo/"&B38,"Link")) -> Link
B39: BSLT11 | C39: 60373688000187 | D39: - | E39: - | F39: - | G39: Outros | H39: 0 | I39: 94102.874 | J39: 58.22 | K39: 104 | L39: 0.55980769 | M39: 78597000 | N39: 1.5478162e+08 | O39: 0.50779285 | P39: 0.79255463 | Q39: - | R39: - | S39: - | T39: - | U39: -0.22373333 | V39: -0.315381 | W39: -0.42127237 | X39: =IF(OR(B39="",G39="FI-Infra"),"",HYPERLINK("https://content.btgpactual.com/research/ativo/https://content.btgpactual.com/research/ativo/"&B39,"Link")) -> Link
B40: BTAG11 | C40: 40771109000147 | D40: BTG Pactual Crédito Agrícola Fiagro FIDC | E40: BTG Pactual | F40: BTG Pactual | G40: FIAgro - FIDC | H40: - | I40: 382757.88 | J40: 97.99 | K40: 112.45192 | L40: 0.87139462 | M40: - | N40: 1.6272754e+08 | O40: - | P40: - | Q40: 0.16124094 | R40: 0.15919992 | S40: 0.01326666 | T40: 1.3 | U40: -0.017023283 | V40: -0.0093838131 | W40: 0.21600428 | X40: =IF(OR(B40="",G40="FI-Infra"),"",HYPERLINK("https://content.btgpactual.com/research/ativo/https://content.btgpactual.com/research/ativo/"&B40,"Link")) -> Link
B41: BTAL11 | C41: 36642244000115 | D41: BTG Pactual Agro Logística FII | E41: BTG Pactual | F41: BTG Pactual | G41: Agronegócio | H41: 0.00321 | I41: 510778.95 | J41: 79.44 | K41: 87.640203 | L41: 0.90643332 | M41: 4.7526855e+08 | N41: 6.9376503e+08 | O41: 0.68505694 | P41: 0.72307831 | Q41: 0.14791037 | R41: 0.1510574 | S41: 0.012588117 | T41: 1 | U41: -0.044015176 | V41: 0.034292129 | W41: 0.18625102 | X41: =IF(OR(B41="",G41="FI-Infra"),"",HYPERLINK("https://content.btgpactual.com/research/ativo/https://content.btgpactual.com/research/ativo/"&B41,"Link")) -> Link
...

Sheet FIAgro
D2: Menu | H2: Menu
T3: Retorno
E4: Características | H4: Volume de Negociação | I4: Fechamento | J4: Máximo | L4: Valor de Mercado | M4: Valor Patrimonial | N4: P/VPA | P4: Dividend Yield (% ao ano) | T4: No Mês | U4: No Ano | V4: LTM | W4: Análises
B5: Código | C5: CNPJ | D5: Nome | E5: Gestor | F5: Administrador | G5: Tipo | H5: Média - 3 Meses (R$) | I5: R$ | J5: R$ | K5: % | L5: R$ | M5: R$ | N5: Atual | O5: 2025 | P5: LTM | Q5: Anualizado | R5: Última Dist. (%) | S5: Div. do Mês (R$) | T5: % | U5: % | V5: % | W5: -
B6: AAZQ11 | C6: 44625826000111 | D6: Az Quest Sole Fiagro-FII | E6: AZ Quest | F6: XP Investimentos | G6: FIAgro - FII | H6: 383825.05 | I6: 6.31 | J6: 8.0364233 | K6: 0.78517517 | L6: 1.5167526e+08 | M6: 2.0764849e+08 | N6: 0.73044239 | O6: 1.0183375 | P6: 0.20166403 | Q6: 0.17115689 | R6: 0.014263074 | S6: 0.09 | T6: -0.049698795 | U6: -0.20007913 | V6: -0.0079482424 | W6: =IF(OR(B6="",G6="FI-Infra"),"",HYPERLINK("https://content.btgpactual.com/research/ativo/https://content.btgpactual.com/research/ativo/"&B6,"Link")) -> Link
B7: AGRX11 | C7: 43951911000107 | D7: Exes Araguaia Fiagro-FII | E7: Éxes Gestora de Recursos | F7: Genial | G7: FIAgro - FII | H7: 274096.55 | I7: 7.81 | J7: 8.5693506 | K7: 0.91138761 | L7: - | M7: 1.8898605e+08 | N7: - | O7: - | P7: 0.18693982 | Q7: 0.184379 | R7: 0.015364917 | S7: 0.12 | T7: -0.0090326633 | U7: 0.041360238 | V7: 0.16925284 | W7: =IF(OR(B7="",G7="FI-Infra"),"",HYPERLINK("https://content.btgpactual.com/research/ativo/https://content.btgpactual.com/research/ativo/"&B7,"Link")) -> Link
B8: BBGO11 | C8: 42592257000120 | D8: BB Fundo de Investimento de Crédito Fiagro-FII | E8: BB Asset Management | F8: BB Asset Management | G8: FIAgro - FII | H8: 322826.9 | I8: 61.74 | J8: 74.979858 | K8: 0.82342114 | L8: 2.4727883e+08 | M8: 3.7340021e+08 | N8: 0.66223537 | O8: 0.83319821 | P8: 0.17039197 | Q8: 0.15549077 | R8: 0.012957564 | S8: 0.8 | T8: -0.045602102 | U8: -0.022997524 | V8: 0.10553178 | W8: =IF(OR(B8="",G8="FI-Infra"),"",HYPERLINK("https://content.btgpactual.com/research/ativo/https://content.btgpactual.com/research/ativo/"&B8,"Link")) -> Link
B9: BRFT11 | C9: 52512069000106 | D9: Bradesco Farmtech Fiagro-FIDC | E9: Bradesco Asset Management | F9: Oliveira Trust | G9: FIAgro - FIDC | H9: 133161.37 | I9: 65 | J9: 87.439805 | K9: 0.74336854 | L9: - | N9: - | O9: - | P9: 0.20169231 | Q9: - | R9: - | S9: - | T9: -0.14453516 | U9: -0.16017564 | V9: -0.10927219 | W9: =IF(OR(B9="",G9="FI-Infra"),"",HYPERLINK("https://content.btgpactual.com/research/ativo/https://content.btgpactual.com/research/ativo/"&B9,"Link")) -> Link
B10: BTAG11 | C10: 40771109000147 | D10: BTG Pactual Crédito Agrícola Fiagro FIDC | E10: BTG Pactual | F10: BTG Pactual | G10: FIAgro - FIDC | H10: 382757.88 | I10: 97.99 | J10: 112.45192 | K10: 0.87139462 | L10: - | M10: 1.6272754e+08 | N10: - | O10: - | P10: 0.16124094 | Q10: 0.15919992 | R10: 0.01326666 | S10: 1.3 | T10: -0.017023283 | U10: -0.0093838131 | V10: 0.21600428 | W10: =IF(OR(B10="",G10="FI-Infra"),"",HYPERLINK("https://content.btgpactual.com/research/ativo/https://content.btgpactual.com/research/ativo/"&B10,"Link")) -> Link
B11: CPTR11 | C11: 42537579000176 | D11: Capitania Agro Strategies - Fiagro-FII | E11: Capitânia | F11: BTG Pactual | G11: FIAgro - FII | H11: 217046.76 | I11: 7.42 | J11: 8.1002747 | K11: 0.91601832 | L11: 1.4709911e+08 | M11: 1.9560432e+08 | N11: 0.75202385 | O11: 1.0043868 | P11: 0.17991914 | Q11: 0.17789757 | R11: 0.014824798 | S11: 0.11 | T11: -0.038877571 | U11: 0.024099856 | V11: 0.17696391 | W11: =IF(OR(B11="",G11="FI-Infra"),"",HYPERLINK("https://content.btgpactual.com/research/ativo/https://content.btgpactual.com/research/ativo/"&B11,"Link")) -> Link
B12: CRAA11 | C12: 48903610000121 | D12: Sparta Fiagro-FII | E12: - | F12: - | G12: FIAgro - FII | H12: 639760.12 | I12: 91 | J12: 98.718462 | K12: 0.92181339 | L12: 215655076 | M12: 2.4203231e+08 | N12: 0.89101772 | O12: - | P12: 0.15989011 | Q12: 0.16483516 | R12: 0.013736264 | S12: 1.25 | T12: 0.0014723678 | U12: 0.049417314 | V12: 0.11972667 | W12: =IF(OR(B12="",G12="FI-Infra"),"",HYPERLINK("https://content.btgpactual.com/research/ativo/https://content.btgpactual.com/research/ativo/"&B12,"Link")) -> Link
B13: DCRA11 | C13: 42888360000111 | D13: Devant Fiagro-FII | E13: Devant Asset | F13: Banco Daycoval | G13: FIAgro - FII | H13: 67361.249 | I13: 6.18 | J13: 7.1951357 | K13: 0.85891362 | L13: 41646433 | M13: 65332307 | N13: 0.63745541 | O13: 0.95266676 | P13: 0.1828479 | Q13: 0.17475728 | R13: 0.014563107 | S13: 0.09 | T13: -0.092458638 | U13: -0.072936 | V13: 0.030944567 | W13: =IF(OR(B13="",G13="FI-Infra"),"",HYPERLINK("https://content.btgpactual.com/research/ativo/https://content.btgpactual.com/research/ativo/"&B13,"Link")) -> Link
B14: EGAF11 | C14: 41224330000148 | D14: Ecoagro I Fiagro-FII | E14: Eco Gestão de Ativos | F14: Vórtx | G14: FIAgro - FII | H14: 936990.99 | I14: 82.21 | J14: 92.495098 | K14: 0.88880386 | L14: 2.5747465e+08 | M14: 3.101973e+08 | N14: 0.83003511 | O14: 1.0237113 | P14: 0.20411142 | Q14: 0.2043547 | R14: 0.017029558 | S14: 1.4 | T14: -0.041137762 | U14: -0.02638018 | V14: 0.043364073 | W14: =IF(OR(B14="",G14="FI-Infra"),"",HYPERLINK("https://content.btgpactual.com/research/ativo/https://content.btgpactual.com/research/ativo/"&B14,"Link")) -> Link
B15: FGAA11 | C15: 42405905000191 | D15: Fg/Agro Fiagro-FII | E15: FG/A Gestora de Recursos | F15: BRL Trust | G15: FIAgro - FII | H15: 730606.68 | I15: 7.8 | J15: 8.8233398 | K15: 0.884019 | L15: 3.516119e+08 | M15: 4.2418194e+08 | N15: 0.82891766 | O15: 1.0392226 | P15: 0.17884615 | Q15: 0.16923077 | R15: 0.014102564 | S15: 0.11 | T15: -0.032241879 | U15: -0.046815881 | V15: 0.086886567 | W15: =IF(OR(B15="",G15="FI-Infra"),"",HYPERLINK("https://content.btgpactual.com/research/ativo/https://content.btgpactual.com/research/ativo/"&B15,"Link")) -> Link
B16: FTCA11 | C16: 42537438000153 | D16: Fyto Recebíveis do Agro Fiagro-FII | E16: Fyto Capital | F16: BTG Pactual | G16: FIAgro - FII | H16: 65696.942 | I16: 6.73 | J16: 9.0827236 | K16: 0.74096717 | L16: 30015477 | M16: 47318287 | N16: 0.63433144 | O16: 0.95597437 | P16: 0.21040119 | Q16: 0.14799406 | R16: 0.012332838 | S16: 0.083 | T16: -0.047196338 | U16: -0.19167391 | V16: -0.051780273 | W16: =IF(OR(B16="",G16="FI-Infra"),"",HYPERLINK("https://content.btgpactual.com/research/ativo/https://content.btgpactual.com/research/ativo/"&B16,"Link")) -> Link
B17: GCRA11 | C17: 37037297000170 | D17: Galapagos Recebiveis do Agronegocio Fiagro-FII | E17: Galapagos Capital | F17: Singulare | G17: FIAgro - FII | H17: 175486.44 | I17: 47.6 | J17: 60.261123 | K17: 0.78989567 | L17: 83341174 | M17: 1.4906844e+08 | N17: 0.55907993 | O17: 0.98534229 | P17: 0.1710084 | Q17: 0.17142857 | R17: 0.014285714 | S17: 0.68 | T17: -0.04157792 | U17: -0.0022174866 | V17: 0.08876723 | W17: =IF(OR(B17="",G17="FI-Infra"),"",HYPERLINK("https://content.btgpactual.com/research/ativo/https://content.btgpactual.com/research/ativo/"&B17,"Link")) -> Link
B18: IAAG11 | C18: 42692399000169 | D18: Inter Amerra - Fiagro-FII | E18: - | F18: - | G18: FIAgro - FII | H18: 214195.09 | I18: 7.13 | J18: 8.4284745 | K18: 0.84594193 | L18: 74538275 | M18: 1.0254469e+08 | N18: 0.72688575 | O18: - | P18: 0.20056101 | Q18: 0.16830295 | R18: 0.014025245 | S18: 0.1 | T18: -0.11975309 | U18: -0.10514327 | V18: 0.10768676 | W18: =IF(OR(B18="",G18="FI-Infra"),"",HYPERLINK("https://content.btgpactual.com/research/ativo/https://content.btgpactual.com/research/ativo/"&B18,"Link")) -> Link
B19: JGPX11 | C19: 42888292000190 | D19: JGP Fiagro-FII | E19: JGP Gestão de Crédito | F19: Banco Daycoval | G19: FIAgro - FII | H19: 460275.61 | I19: 57.6 | J19: 68.139568 | K19: 0.84532382 | L19: 1.2333588e+08 | M19: 2.0592887e+08 | N19: 0.5989247 | O19: 0.99470902 | P19: 0.19965278 | Q19: 0.20833333 | R19: 0.017361111 | S19: 1 | T19: -0.018739353 | U19: -0.15467618 | V19: -0.046783319 | W19: =IF(OR(B19="",G19="FI-Infra"),"",HYPERLINK("https://content.btgpactual.com/research/ativo/https://content.btgpactual.com/research/ativo/"&B19,"Link")) -> Link
B20: KDOL11 | C20: 51641681000108 | D20: Kinea Agro Income USD Fiagro-FII | E20: Kinea | F20: Intrag | G20: FIAgro - FII | H20: 77320.659 | I20: 87 | J20: 96.533234 | K20: 0.90124402 | L20: 58375434 | M20: 65919150 | N20: 0.88556109 | O20: - | P20: 0.060574713 | Q20: 0.062068966 | R20: 0.0051724138 | S20: 0.45 | T20: 0.035098156 | U20: -0.041723508 | V20: -0.013177087 | W20: =IF(OR(B20="",G20="FI-Infra"),"",HYPERLINK("https://content.btgpactual.com/research/ativo/https://content.btgpactual.com/research/ativo/"&B20,"Link")) -> Link
B21: KNCA11 | C21: 41745701000137 | D21: Kinea Crédito Agro Fiagro-FII | E21: Kinea | F21: Intrag | G21: FIAgro - FII | H21: 3436877.5 | I21: 87 | J21: 92.570243 | K21: 0.93982685 | L21: 1879192953 | M21: 2.2175578e+09 | N21: 0.84741553 | O21: 1.0372589 | P21: 0.14816092 | Q21: 0.13793103 | R21: 0.011494253 | S21: 1 | T21: -0.025100852 | U21: -0.022068097 | V21: 0.07401949 | W21: =IF(OR(B21="",G21="FI-Infra"),"",HYPERLINK("https://content.btgpactual.com/research/ativo/https://content.btgpactual.com/research/ativo/"&B21,"Link")) -> Link
B22: KOPA11 | C22: 51475461000151 | D22: Kinea Oportunidades Agro I Fiagro-FII | E22: Kinea | F22: Intrag | G22: FIAgro - FII | H22: 150651.8 | I22: 222.22 | J22: 272.72078 | K22: 0.81482605 | L22: 78816323 | M22: 3.4988538e+08 | N22: 0.22526326 | O22: - | P22: 0.47092971 | Q22: 0.21600216 | R22: 0.01800018 | S22: 4 | T22: -0.16844318 | U22: -0.013127368 | V22: 0.061449462 | W22: =IF(OR(B22="",G22="FI-Infra"),"",HYPERLINK("https://content.btgpactual.com/research/ativo/https://content.btgpactual.com/research/ativo/"&B22,"Link")) -> Link
B23: LSAG11 | C23: 42592476000109 | D23: Leste Fiagro | E23: Leste Credit Gestão de Recursos | F23: Genial | G23: FIAgro - FII | H23: 71105.448 | I23: 74.24 | J23: 82.935557 | K23: 0.89515285 | L23: 74932956 | M23: 99162873 | N23: 0.75565536 | O23: 1.121254 | P23: 0.17281789 | Q23: 0.16163793 | R23: 0.013469828 | S23: 1 | T23: -0.039710257 | U23: -0.026481475 | V23: 0.16157391 | W23: =IF(OR(B23="",G23="FI-Infra"),"",HYPERLINK("https://content.btgpactual.com/research/ativo/https://content.btgpactual.com/research/ativo/"&B23,"Link")) -> Link
B24: NEXG11 | C24: 52044477000172 | D24: NEX Crédito Agro Fiagro-FII | E24: NEX Gestão de Recursos | F24: Vórtx | G24: FIAgro - FII | H24: 273021.86 | I24: 129.5 | J24: 133.07308 | K24: 0.97314947 | L24: 159614448 | M24: 69989312 | N24: 1.2924223 | O24: - | P24: 0.085482625 | Q24: 0.085250965 | R24: 0.0071042471 | S24: 0.92 | T24: -0.026850529 | U24: 0.099007518 | V24: 0.29527162 | W24: =IF(OR(B24="",G24="FI-Infra"),"",HYPERLINK("https://content.btgpactual.com/research/ativo/https://content.btgpactual.com/research/ativo/"&B24,"Link")) -> Link
B25: OIAG11 | C25: 41218352000103 | D25: Ourinvest Innovation Fiagro-FII | E25: Fator ORE | F25: Singulare | G25: FIAgro - FII | H25: 122735.86 | I25: 7.83 | J25: 8.8064094 | K25: 0.88912514 | L25: 70728382 | M25: 88536764 | N25: 0.79885891 | O25: 1.0433465 | P25: 0.18199234 | Q25: 0.17624521 | R25: 0.014687101 | S25: 0.115 | T25: -0.023047154 | U25: 0.013168618 | V25: 0.20520693 | W25: =IF(OR(B25="",G25="FI-Infra"),"",HYPERLINK("https://content.btgpactual.com/research/ativo/https://content.btgpactual.com/research/ativo/"&B25,"Link")) -> Link
B26: PLCA11 | C26: 41272747000186 | D26: Plural BRB Crédito Agro Fiagro-FII | E26: Plural Gestão de Recursos | F26: Genial | G26: FIAgro - FII | H26: 54387.55 | I26: 69.4 | J26: 75.932367 | K26: 0.91397124 | L26: 38657119 | M26: 53136654 | N26: 0.72750382 | O26: 0.99815874 | P26: 0.17795389 | Q26: 0.1815562 | R26: 0.015129683 | S26: 1.05 | T26: -0.045916965 | U26: 0.063663994 | V26: 0.16435742 | W26: =IF(OR(B26="",G26="FI-Infra"),"",HYPERLINK("https://content.btgpactual.com/research/ativo/https://content.btgpactual.com/research/ativo/"&B26,"Link")) -> Link
B27: RURA11 | C27: 42479593000160 | D27: Itaú Asset Rural Fiagro-FII | E27: Itaú Unibanco | F27: Intrag | G27: FIAgro - FII | H27: 2726907.4 | I27: 8.15 | J27: 8.6817948 | K27: 0.93874598 | L27: 1.304811e+09 | M27: 1.6388061e+09 | N27: 0.79619607 | O27: 1.0206706 | P27: 0.16539877 | Q27: 0.16196319 | R27: 0.013496933 | S27: 0.11 | T27: 0.0024600246 | U27: 0.028984216 | V27: 0.18608605 | W27: =IF(OR(B27="",G27="FI-Infra"),"",HYPERLINK("https://content.btgpactual.com/research/ativo/https://content.btgpactual.com/research/ativo/"&B27,"Link")) -> Link
B28: RZAG11 | C28: 40413979000144 | D28: Riza Fiagro-FII | E28: Riza | F28: Genial | G28: FIAgro - FII | H28: 1357714.3 | I28: 8.31 | J28: 8.8756433 | K28: 0.93627017 | L28: 5.6541593e+08 | M28: 6.549998e+08 | N28: 0.86323069 | O28: 0.96392798 | P28: 0.17990373 | Q28: 0.18050542 | R28: 0.015042118 | S28: 0.125 | T28: -0.00060132291 | U28: -0.026865784 | V28: 0.11965199 | W28: =IF(OR(B28="",G28="FI-Infra"),"",HYPERLINK("https://content.btgpactual.com/research/ativo/https://content.btgpactual.com/research/ativo/"&B28,"Link")) -> Link
B29: SNAG11 | C29: 28152777000190 | D29: Suno Agro Fiagro-FII | E29: Suno | F29: Singulare | G29: FIAgro - FII | H29: 1954324.8 | I29: 9.69 | J29: 10.307168 | K29: 0.94012245 | L29: 5.8857402e+08 | M29: 6.2655227e+08 | N29: 0.93938535 | O29: 1.0063385 | P29: 0.1630547 | Q29: 0.14860681 | R29: 0.012383901 | S29: 0.12 | T29: -0.0062154953 | U29: -0.027556445 | V29: 0.19626793 | W29: =IF(OR(B29="",G29="FI-Infra"),"",HYPERLINK("https://content.btgpactual.com/research/ativo/https://content.btgpactual.com/research/ativo/"&B29,"Link")) -> Link
B30: SNFZ11 | C30: 53313475000102 | D30: Suno Fazendas Fiagro-FII | E30: Suno | F30: Singulare | G30: FIAgro - FII | H30: 218214.23 | I30: 9.12 | J30: 9.5432075 | K30: 0.95565354 | L30: 1.1025995e+08 | M30: 62625277 | N30: 0.90324983 | O30: - | P30: 0.13157895 | Q30: 0.13157895 | R30: 0.010964912 | S30: 0.1 | T30: -0.0088666552 | U30: -0.018741558 | V30: 0.059048197 | W30: =IF(OR(B30="",G30="FI-Infra"),"",HYPERLINK("https://content.btgpactual.com/research/ativo/https://content.btgpactual.com/research/ativo/"&B30,"Link")) -> Link
B31: VCRA11 | C31: 42502827000143 | D31: Vectis Datagro Crédito Agronegócio Fiagro-FII | E31: Vectis | F31: Intrag | G31: FIAgro - FII | H31: 667907.5 | I31: 51.32 | J31: 63.460844 | K31: 0.80868764 | L31: 2.3575992e+08 | M31: 4.6851258e+08 | N31: 0.50320937 | O31: 1.0268476 | P31: 0.22213562 | Q31: 0.17537023 | R31: 0.014614186 | S31: 0.75 | T31: -0.10248339 | U31: -0.10274633 | V31: 0.00018462308 | W31: =IF(OR(B31="",G31="FI-Infra"),"",HYPERLINK("https://content.btgpactual.com/research/ativo/https://content.btgpactual.com/research/ativo/"&B31,"Link")) -> Link
B32: VGIA11 | C32: 41081088000109 | D32: Valora CRA Fiagro-FII | E32: Valora | F32: BTG Pactual | G32: FIAgro - FII | H32: 2956539.2 | I32: 8.42 | J32: 9.5380985 | K32: 0.88277554 | L32: 7.2795209e+08 | M32: 8.354651e+08 | N32: 0.87131358 | O32: 1.0339267 | P32: 0.195962 | Q32: 0.18527316 | R32: 0.01543943 | S32: 0.13 | T32: 0.033089127 | U32: -0.044357046 | V32: 0.12187365 | W32: =IF(OR(B32="",G32="FI-Infra"),"",HYPERLINK("https://content.btgpactual.com/research/ativo/https://content.btgpactual.com/research/ativo/"&B32,"Link")) -> Link
B33: XPCA11 | C33: 41269527000101 | D33: XP Crédito Agrícola Fiagro-FII | E33: XP | F33: XP Investimentos | G33: FIAgro - FII | H33: 602436.99 | I33: 7.16 | J33: 8.2248992 | K33: 0.87052738 | L33: 3.2594522e+08 | M33: 4.3900465e+08 | N33: 0.74246417 | O33: 0.99799629 | P33: 0.18156425 | Q33: 0.16759777 | R33: 0.01396648 | S33: 0.1 | T33: -0.057894737 | U33: -0.060006581 | V33: 0.088638648 | W33: =IF(OR(B33="",G33="FI-Infra"),"",HYPERLINK("https://content.btgpactual.com/research/ativo/https://content.btgpactual.com/research/ativo/"&B33,"Link")) -> Link

Sheet FI-Infra
D2: Menu | H2: Menu
Q3: Retorno
E4: Características | H4: Volume de Negociação | I4: Fechamento | J4: Máximo | L4: Valor de Mercado | M4: Valor Patrimonial | N4: P/VPA | O4: Pagamentos | P4: Pagamentos | Q4: No Mês | R4: No Ano | S4: LTM
B5: Código | C5: CNPJ | D5: Nome | E5: Gestor | F5: Administrador | G5: Tipo | H5: Média - 3 Meses (R$) | I5: R$ | J5: R$ | K5: % | L5: R$ | M5: R$ | N5: Atual | O5: % | P5: R$/cota | Q5: % | R5: % | S5: %
B6: BDIF11 | C6: 40502607000194 | D6: BTG Pactual Dívida Infra FIC FI-Infra | E6: BTG Pactual | F6: BTG Pactual | G6: FI-Infra | H6: 2152614.5 | I6: 68.34 | J6: 73.712369 | K6: 0.92711712 | L6: 1.2386611e+09 | M6: 1.4272615e+09 | N6: 0.86785855 | O6: 0.012437811 | P6: 0.85 | Q6: -0.013921388 | R6: 0.026322057 | S6: 0.07456221
B7: BIDB11 | C7: 42294971000131 | D7: Inter Infra FIC FI - Infra listado | E7: Inter | F7: Inter | G7: FI-Infra | H7: 201660.78 | I7: 74 | J7: 78.148844 | K7: 0.946911 | L7: 1.8468646e+08 | M7: 1.9481402e+08 | N7: 0.94801424 | O7: 0.013513514 | P7: 1 | Q7: -0.043927649 | R7: 0.021997345 | S7: 0.10698394
B8: BINC11 | C8: 55239865000105 | D8: Bradesco FIC FI Renda Fixa Infra CDI | E8: Bradesco Asset Management | F8: Banco Bradesco | G8: FI-Infra | H8: 785178.16 | I8: 102.9 | J8: 105.99 | K8: 0.97084631 | L8: 1.1953158e+09 | M8: 1.1703078e+09 | N8: 1.0213688 | O8: 0.014577259 | P8: 1.5 | Q8: -0.010957324 | R8: 0.13091287 | S8: 0.26665811
B9: BODB11 | C9: 41771670000199 | D9: Bocaina FIC FI-Infra | E9: Bocaina Capital | F9: BTG Pactual | G9: FI-Infra | H9: 921585.67 | I9: 7.13 | J9: 7.7079948 | K9: 0.9250136 | L9: 4.6257371e+08 | M9: 5.1896933e+08 | N9: 0.8913315 | O9: 0.012622721 | P9: 0.09 | Q9: -0.054376658 | R9: -0.01110907 | S9: 0.14308479
B10: CDII11 | C10: 48973783000116 | D10: Sparta Infra CDI FIC FI-Infra | E10: Sparta | F10: BTG Pactual | G10: FI-Infra | H10: 7124571 | I10: 95.71 | J10: 101.91327 | K10: 0.93913188 | L10: 2.6302197e+09 | M10: 2.7939017e+09 | N10: 0.94141454 | O10: 0.010448229 | P10: 1 | Q10: -0.029408782 | R10: -0.060782865 | S10: 0.042360146
B11: CPTI11 | C11: 38065012000177 | D11: Capitânia Infra FIC FIRF | E11: Capitânia | F11: BTG Pactual | G11: FI-Infra | H11: 2258273.3 | I11: 81.9 | J11: 86.075775 | K11: 0.95148722 | L11: 1.1124226e+09 | M11: 1.226901e+09 | N11: 0.90669298 | O11: 0.014041514 | P11: 1.15 | Q11: -0.041924296 | R11: 0.036045659 | S11: 0.17733016
B12: DIVS11 | C12: 58390457000130 | D12: Sparta Inflação Longa | E12: Sparta | F12: BNY | G12: FI-Infra | H12: 1335708 | I12: 92.96 | J12: 106.36944 | K12: 0.87393519 | L12: 9.5342381e+08 | M12: 9.9434637e+08 | N12: 0.95884477 | O12: 0.012908778 | P12: 1.2 | Q12: -0.017855256 | R12: 0.027603186 | S12: 0.030152803
B13: IFRA11 | C13: 34633510000118 | D13: Itaú FIC FI de Infraestrutura | E13: Itaú Unibanco | F13: Intrag | G13: FI-Infra | H13: 2172046.6 | I13: 89.5 | J13: 98.079426 | K13: 0.91252574 | L13: 1.3865382e+09 | M13: 1.4775307e+09 | N13: 0.93841583 | O13: 0.010055866 | P13: 0.9 | Q13: -0.033477322 | R13: -0.032459095 | S13: 0.062158534
B14: IFRI11 | C14: 53556099000179 | D14: Itaú FIC FI de Infraestrutura CDI | E14: Itaú Unibanco | F14: Intrag | G14: FI-Infra | H14: 1877729.8 | I14: 99.93 | J14: 102 | K14: 0.97970588 | L14: 1.4965015e+09 | M14: 1.4890543e+09 | N14: 1.0050013 | O14: 0.013009106 | P14: 1.3 | Q14: -0.016824085 | R14: 0.060621152 | S14: 0.18162034
B15: IRIF11 | C15: 55940336000126 | D15: Iridium Infra | E15: Iridium | F15: BTG Pactual | G15: FI-Infra | H15: 52186.328 | I15: 8.14 | J15: 9.2630781 | K15: 0.87875757 | L15: 36260021 | M15: 45619674 | N15: 0.79483296 | O15: 0.012285012 | P15: 0.1 | Q15: -0.037744771 | R15: -0.043184509 | S15: 0.11760096
B16: JMBI11 | C16: 55276939000175 | D16: Jive Mauá Bossanova FIC FI-Infra | E16: Jive | F16: XP | G16: FI-Infra | H16: 970935.4 | I16: 81.18 | J16: 87.704456 | K16: 0.92560861 | L16: 3.551625e+08 | M16: 4.4283852e+08 | N16: 0.80201356 | O16: 0.015028332 | P16: 1.22 | Q16: -0.02263424 | R16: 0.038905521 | S16: 0.10506249
B17: JURO11 | C17: 42730834000100 | D17: Sparta Infra FIC FI-Infra | E17: Sparta | F17: BTG Pactual | G17: FI-Infra | H17: 5495610.7 | I17: 94.05 | J17: 102.27267 | K17: 0.91960051 | L17: 1.9347662e+09 | M17: 2.0770137e+09 | N17: 0.93151348 | O17: 0.0079744817 | P17: 0.75 | Q17: -0.024377593 | R17: -0.034731463 | S17: 0.07546793
... B23: XPID11 | C23: 37404867000112 | D23: XP FIC FI-Infra | E23: XP | F23: Genial | G23: FI-Infra | H23: 108940.24 | I23: 48.89 | J23: 61.921475 | K23: 0.78954837 | L23: 1.5475953e+08 | M23: 2.3241536e+08 | N23: 0.66587483 | O23: 0.01534056 | P23: 0.75 | Q23: 0.011587006 | R23: 0.16803078 | S23: 0.041548098

Sheet Segmentos
L2: Menu | M2: Stock Guide
B4: Análise Segmentos
B5: Segmento | C5: Part. IFIX | D5: Volume de Negociação | E5: Valor de Mercado | F5: Valor Patrimonial | G5: P/VPA Atual | H5: P/VPA 2025 | I5: Dividend Yield LTM | J5: Dividend Yield Anualizado | K5: Retorno no Mês | L5: Retorno no Ano | M5: Retorno LTM
B6: Nome | C6: Total (%) | D6: Média Diária (R$) | E6: Total (R$) | F6: Total (R$) | G6: Média | H6: Média | I6: Média (% ao ano) | J6: Média (% ao ano) | K6: Média (%) | L6: Média (%) | M6: Média (%)
B7: Recebível | C7: =SUMIFS('Stock Guide'!H:H,'Stock Guide'!$G:$G,Segmentos!$B7) -> 0.36761 | D7: =AVERAGEIFS('Stock Guide'!I:I,'Stock Guide'!$G:$G,Segmentos!$B7) -> 1876793.9 | E7: =SUMIFS('Stock Guide'!M:M,'Stock Guide'!$G:$G,Segmentos!$B7) -> 5.6870845e+10 | F7: =SUMIFS('Stock Guide'!N:N,'Stock Guide'!$G:$G,Segmentos!$B7) -> 6.6479083e+10 | G7: =AVERAGEIFS('Stock Guide'!O:O,'Stock Guide'!$G:$G,Segmentos!$B7) -> 0.78179103 | H7: =AVERAGEIFS('Stock Guide'!P:P,'Stock Guide'!$G:$G,Segmentos!$B7) -> 0.86063519 | I7: =AVERAGEIFS('Stock Guide'!Q:Q,'Stock Guide'!$G:$G,Segmentos!$B7) -> 0.16614556 | J7: =AVERAGEIFS('Stock Guide'!R:R,'Stock Guide'!$G:$G,Segmentos!$B7) -> 0.15990203 | K7: =AVERAGEIFS('Stock Guide'!U:U,'Stock Guide'!$G:$G,Segmentos!$B7) -> -0.03196602 | L7: =AVERAGEIFS('Stock Guide'!V:V,'Stock Guide'!$G:$G,Segmentos!$B7) -> -0.027109577 | M7: =AVERAGEIFS('Stock Guide'!W:W,'Stock Guide'!$G:$G,Segmentos!$B7) -> 0.048648218
B8: Galpão Logístico | C8: =SUMIFS('Stock Guide'!H:H,'Stock Guide'!$G:$G,Segmentos!$B8) -> 0.18024 | D8: =AVERAGEIFS('Stock Guide'!I:I,'Stock Guide'!$G:$G,Segmentos!$B8) -> 3125206.6 | E8: =SUMIFS('Stock Guide'!M:M,'Stock Guide'!$G:$G,Segmentos!$B8) -> 3.2929979e+10 | F8: =SUMIFS('Stock Guide'!N:N,'Stock Guide'!$G:$G,Segmentos!$B8) -> 3.8725582e+10 | G8: =AVERAGEIFS('Stock Guide'!O:O,'Stock Guide'!$G:$G,Segmentos!$B8) -> 0.79534334 | H8: =AVERAGEIFS('Stock Guide'!P:P,'Stock Guide'!$G:$G,Segmentos!$B8) -> 0.8761547 | I8: =AVERAGEIFS('Stock Guide'!Q:Q,'Stock Guide'!$G:$G,Segmentos!$B8) -> 0.11209998 | J8: =AVERAGEIFS('Stock Guide'!R:R,'Stock Guide'!$G:$G,Segmentos!$B8) -> 0.10854653 | K8: =AVERAGEIFS('Stock Guide'!U:U,'Stock Guide'!$G:$G,Segmentos!$B8) -> -0.027476579 | L8: =AVERAGEIFS('Stock Guide'!V:V,'Stock Guide'!$G:$G,Segmentos!$B8) -> -0.045070883 | M8: =AVERAGEIFS('Stock Guide'!W:W,'Stock Guide'!$G:$G,Segmentos!$B8) -> 0.076591985
B9: Shopping Center | C9: =SUMIFS('Stock Guide'!H:H,'Stock Guide'!$G:$G,Segmentos!$B9) -> 0.11835 | D9: =AVERAGEIFS('Stock Guide'!I:I,'Stock Guide'!$G:$G,Segmentos!$B9) -> 3558069.7 | E9: =SUMIFS('Stock Guide'!M:M,'Stock Guide'!$G:$G,Segmentos!$B9) -> 2.4299827e+10 | F9: =SUMIFS('Stock Guide'!N:N,'Stock Guide'!$G:$G,Segmentos!$B9) -> 2.959225e+10 | G9: =AVERAGEIFS('Stock Guide'!O:O,'Stock Guide'!$G:$G,Segmentos!$B9) -> 0.79206712 | H9: =AVERAGEIFS('Stock Guide'!P:P,'Stock Guide'!$G:$G,Segmentos!$B9) -> 0.81495066 | I9: =AVERAGEIFS('Stock Guide'!Q:Q,'Stock Guide'!$G:$G,Segmentos!$B9) -> 0.10760615 | J9: =AVERAGEIFS('Stock Guide'!R:R,'Stock Guide'!$G:$G,Segmentos!$B9) -> 0.092415897 | K9: =AVERAGEIFS('Stock Guide'!U:U,'Stock Guide'!$G:$G,Segmentos!$B9) -> -0.034986054 | L9: =AVERAGEIFS('Stock Guide'!V:V,'Stock Guide'!$G:$G,Segmentos!$B9) -> -0.03700172 | M9: =AVERAGEIFS('Stock Guide'!W:W,'Stock Guide'!$G:$G,Segmentos!$B9) -> 0.057332756
B10: Hedge Fund | C10: =SUMIFS('Stock Guide'!H:H,'Stock Guide'!$G:$G,Segmentos!$B10) -> 0.07365 | D10: =AVERAGEIFS('Stock Guide'!I:I,'Stock Guide'!$G:$G,Segmentos!$B10) -> 1633937.1 | E10: =SUMIFS('Stock Guide'!M:M,'Stock Guide'!$G:$G,Segmentos!$B10) -> 1.2270998e+10 | F10: =SUMIFS('Stock Guide'!N:N,'Stock Guide'!$G:$G,Segmentos!$B10) -> 1.5065138e+10 | G10: =AVERAGEIFS('Stock Guide'!O:O,'Stock Guide'!$G:$G,Segmentos!$B10) -> 0.83859445 | H10: =AVERAGEIFS('Stock Guide'!P:P,'Stock Guide'!$G:$G,Segmentos!$B10) -> 0.89496964 | I10: =AVERAGEIFS('Stock Guide'!Q:Q,'Stock Guide'!$G:$G,Segmentos!$B10) -> 0.15013515 | J10: =AVERAGEIFS('Stock Guide'!R:R,'Stock Guide'!$G:$G,Segmentos!$B10) -> 0.14486763 | K10: =AVERAGEIFS('Stock Guide'!U:U,'Stock Guide'!$G:$G,Segmentos!$B10) -> -0.027127969 | L10: =AVERAGEIFS('Stock Guide'!V:V,'Stock Guide'!$G:$G,Segmentos!$B10) -> -0.015378938 | M10: =AVERAGEIFS('Stock Guide'!W:W,'Stock Guide'!$G:$G,Segmentos!$B10) -> 0.081350971
B11: Laje Corporativa | C11: =SUMIFS('Stock Guide'!H:H,'Stock Guide'!$G:$G,Segmentos!$B11) -> 0.06532 | D11: =AVERAGEIFS('Stock Guide'!I:I,'Stock Guide'!$G:$G,Segmentos!$B11) -> 1307854.4 | E11: =SUMIFS('Stock Guide'!M:M,'Stock Guide'!$G:$G,Segmentos!$B11) -> 1.2424207e+10 | F11: =SUMIFS('Stock Guide'!N:N,'Stock Guide'!$G:$G,Segmentos!$B11) -> 1.9888354e+10 | G11: =AVERAGEIFS('Stock Guide'!O:O,'Stock Guide'!$G:$G,Segmentos!$B11) -> 0.6322556 | H11: =AVERAGEIFS('Stock Guide'!P:P,'Stock Guide'!$G:$G,Segmentos!$B11) -> 0.67987344 | I11: =AVERAGEIFS('Stock Guide'!Q:Q,'Stock Guide'!$G:$G,Segmentos!$B11) -> 0.11182231 | J11: =AVERAGEIFS('Stock Guide'!R:R,'Stock Guide'!$G:$G,Segmentos!$B11) -> 0.13073001 | K11: =AVERAGEIFS('Stock Guide'!U:U,'Stock Guide'!$G:$G,Segmentos!$B11) -> -0.019245959 | L11: =AVERAGEIFS('Stock Guide'!V:V,'Stock Guide'!$G:$G,Segmentos!$B11) -> -0.0082131217 | M11: =AVERAGEIFS('Stock Guide'!W:W,'Stock Guide'!$G:$G,Segmentos!$B11) -> 0.12871187
B12: Renda Urbana | C12: =SUMIFS('Stock Guide'!H:H,'Stock Guide'!$G:$G,Segmentos!$B12) -> 0.08267 | D12: =AVERAGEIFS('Stock Guide'!I:I,'Stock Guide'!$G:$G,Segmentos!$B12) -> 5061768.8 | E12: =SUMIFS('Stock Guide'!M:M,'Stock Guide'!$G:$G,Segmentos!$B12) -> 1.2827437e+10 | F12: =SUMIFS('Stock Guide'!N:N,'Stock Guide'!$G:$G,Segmentos!$B12) -> 1.5074284e+10 | G12: =AVERAGEIFS('Stock Guide'!O:O,'Stock Guide'!$G:$G,Segmentos!$B12) -> 0.87504221 | H12: =AVERAGEIFS('Stock Guide'!P:P,'Stock Guide'!$G:$G,Segmentos!$B12) -> 0.95833695 | I12: =AVERAGEIFS('Stock Guide'!Q:Q,'Stock Guide'!$G:$G,Segmentos!$B12) -> 0.14673631 | J12: =AVERAGEIFS('Stock Guide'!R:R,'Stock Guide'!$G:$G,Segmentos!$B12) -> 0.11614244 | K12: =AVERAGEIFS('Stock Guide'!U:U,'Stock Guide'!$G:$G,Segmentos!$B12) -> -0.043774239 | L12: =AVERAGEIFS('Stock Guide'!V:V,'Stock Guide'!$G:$G,Segmentos!$B12) -> -0.016001281 | M12: =AVERAGEIFS('Stock Guide'!W:W,'Stock Guide'!$G:$G,Segmentos!$B12) -> 0.1186824
B13: Híbrido | C13: =SUMIFS('Stock Guide'!H:H,'Stock Guide'!$G:$G,Segmentos!$B13) -> 0.04733 | D13: =AVERAGEIFS('Stock Guide'!I:I,'Stock Guide'!$G:$G,Segmentos!$B13) -> 1719745.4 | E13: =SUMIFS('Stock Guide'!M:M,'Stock Guide'!$G:$G,Segmentos!$B13) -> 7.3838433e+09 | F13: =SUMIFS('Stock Guide'!N:N,'Stock Guide'!$G:$G,Segmentos!$B13) -> 8.4335581e+09 | G13: =AVERAGEIFS('Stock Guide'!O:O,'Stock Guide'!$G:$G,Segmentos!$B13) -> 0.7588104 | H13: =AVERAGEIFS('Stock Guide'!P:P,'Stock Guide'!$G:$G,Segmentos!$B13) -> 0.82167984 | I13: =AVERAGEIFS('Stock Guide'!Q:Q,'Stock Guide'!$G:$G,Segmentos!$B13) -> 0.11421085 | J13: =AVERAGEIFS('Stock Guide'!R:R,'Stock Guide'!$G:$G,Segmentos!$B13) -> 0.11086549 | K13: =AVERAGEIFS('Stock Guide'!U:U,'Stock Guide'!$G:$G,Segmentos!$B13) -> -0.024056091 | L13: =AVERAGEIFS('Stock Guide'!V:V,'Stock Guide'!$G:$G,Segmentos!$B13) -> -0.014951237 | M13: =AVERAGEIFS('Stock Guide'!W:W,'Stock Guide'!$G:$G,Segmentos!$B13) -> 0.11084411
B14: Fundo de Fundos | C14: =SUMIFS('Stock Guide'!H:H,'Stock Guide'!$G:$G,Segmentos!$B14) -> 0.02417 | D14: =AVERAGEIFS('Stock Guide'!I:I,'Stock Guide'!$G:$G,Segmentos!$B14) -> 568847.14 | E14: =SUMIFS('Stock Guide'!M:M,'Stock Guide'!$G:$G,Segmentos!$B14) -> 5.4280166e+09 | F14: =SUMIFS('Stock Guide'!N:N,'Stock Guide'!$G:$G,Segmentos!$B14) -> 6.6673863e+09 | G14: =AVERAGEIFS('Stock Guide'!O:O,'Stock Guide'!$G:$G,Segmentos!$B14) -> 0.82129622 | H14: =AVERAGEIFS('Stock Guide'!P:P,'Stock Guide'!$G:$G,Segmentos!$B14) -> 0.83882072 | I14: =AVERAGEIFS('Stock Guide'!Q:Q,'Stock Guide'!$G:$G,Segmentos!$B14) -> 0.14336735 | J14: =AVERAGEIFS('Stock Guide'!R:R,'Stock Guide'!$G:$G,Segmentos!$B14) -> 0.13768934 | K14: =AVERAGEIFS('Stock Guide'!U:U,'Stock Guide'!$G:$G,Segmentos!$B14) -> -0.024372758 | L14: =AVERAGEIFS('Stock Guide'!V:V,'Stock Guide'!$G:$G,Segmentos!$B14) -> 0.0075174358 | M14: =AVERAGEIFS('Stock Guide'!W:W,'Stock Guide'!$G:$G,Segmentos!$B14) -> 0.11882949
B15: Agronegócio | C15: =SUMIFS('Stock Guide'!H:H,'Stock Guide'!$G:$G,Segmentos!$B15) -> 0.01396 | D15: =AVERAGEIFS('Stock Guide'!I:I,'Stock Guide'!$G:$G,Segmentos!$B15) -> 982889.21 | E15: =SUMIFS('Stock Guide'!M:M,'Stock Guide'!$G:$G,Segmentos!$B15) -> 2.6351965e+09 | F15: =SUMIFS('Stock Guide'!N:N,'Stock Guide'!$G:$G,Segmentos!$B15) -> 3.2791753e+09 | G15: =AVERAGEIFS('Stock Guide'!O:O,'Stock Guide'!$G:$G,Segmentos!$B15) -> 0.77154218 | H15: =AVERAGEIFS('Stock Guide'!P:P,'Stock Guide'!$G:$G,Segmentos!$B15) -> 0.77861192 | I15: =AVERAGEIFS('Stock Guide'!Q:Q,'Stock Guide'!$G:$G,Segmentos!$B15) -> 0.12846861 | J15: =AVERAGEIFS('Stock Guide'!R:R,'Stock Guide'!$G:$G,Segmentos!$B15) -> 0.14006193 | K15: =AVERAGEIFS('Stock Guide'!U:U,'Stock Guide'!$G:$G,Segmentos!$B15) -> -0.010602859 | L15: =AVERAGEIFS('Stock Guide'!V:V,'Stock Guide'!$G:$G,Segmentos!$B15) -> 0.12914134 | M15: =AVERAGEIFS('Stock Guide'!W:W,'Stock Guide'!$G:$G,Segmentos!$B15) -> 0.30807177
B16: Desenvolvimento | C16: =SUMIFS('Stock Guide'!H:H,'Stock Guide'!$G:$G,Segmentos!$B16) -> 0.00845 | D16: =AVERAGEIFS('Stock Guide'!I:I,'Stock Guide'!$G:$G,Segmentos!$B16) -> 1260937 | E16: =SUMIFS('Stock Guide'!M:M,'Stock Guide'!$G:$G,Segmentos!$B16) -> 1.6006086e+09 | F16: =SUMIFS('Stock Guide'!N:N,'Stock Guide'!$G:$G,Segmentos!$B16) -> 3.606676e+09 | G16: =AVERAGEIFS('Stock Guide'!O:O,'Stock Guide'!$G:$G,Segmentos!$B16) -> 0.72542782 | H16: =AVERAGEIFS('Stock Guide'!P:P,'Stock Guide'!$G:$G,Segmentos!$B16) -> 0.84389661 | I16: =AVERAGEIFS('Stock Guide'!Q:Q,'Stock Guide'!$G:$G,Segmentos!$B16) -> 0.24162841 | J16: =AVERAGEIFS('Stock Guide'!R:R,'Stock Guide'!$G:$G,Segmentos!$B16) -> 0.25826212 | K16: =AVERAGEIFS('Stock Guide'!U:U,'Stock Guide'!$G:$G,Segmentos!$B16) -> -0.083223892 | L16: =AVERAGEIFS('Stock Guide'!V:V,'Stock Guide'!$G:$G,Segmentos!$B16) -> -0.20292075 | M16: =AVERAGEIFS('Stock Guide'!W:W,'Stock Guide'!$G:$G,Segmentos!$B16) -> 0.042485033
B17: Agência Bancária | C17: =SUMIFS('Stock Guide'!H:H,'Stock Guide'!$G:$G,Segmentos!$B17) -> 0.00951 | D17: =AVERAGEIFS('Stock Guide'!I:I,'Stock Guide'!$G:$G,Segmentos!$B17) -> 320210.97 | E17: =SUMIFS('Stock Guide'!M:M,'Stock Guide'!$G:$G,Segmentos!$B17) -> 1.7479308e+09 | F17: =SUMIFS('Stock Guide'!N:N,'Stock Guide'!$G:$G,Segmentos!$B17) -> 2.027914e+09 | G17: =AVERAGEIFS('Stock Guide'!O:O,'Stock Guide'!$G:$G,Segmentos!$B17) -> 0.78473812 | H17: =AVERAGEIFS('Stock Guide'!P:P,'Stock Guide'!$G:$G,Segmentos!$B17) -> 0.88774273 | I17: =AVERAGEIFS('Stock Guide'!Q:Q,'Stock Guide'!$G:$G,Segmentos!$B17) -> 0.15429272 | J17: =AVERAGEIFS('Stock Guide'!R:R,'Stock Guide'!$G:$G,Segmentos!$B17) -> 0.13443779 | K17: =AVERAGEIFS('Stock Guide'!U:U,'Stock Guide'!$G:$G,Segmentos!$B17) -> -0.017890658 | L17: =AVERAGEIFS('Stock Guide'!V:V,'Stock Guide'!$G:$G,Segmentos!$B17) -> -0.08733346 | M17: =AVERAGEIFS('Stock Guide'!W:W,'Stock Guide'!$G:$G,Segmentos!$B17) -> 0.010780355
B18: Hotel | C18: =SUMIFS('Stock Guide'!H:H,'Stock Guide'!$G:$G,Segmentos!$B18) -> 0.00265 | D18: =AVERAGEIFS('Stock Guide'!I:I,'Stock Guide'!$G:$G,Segmentos!$B18) -> 458137.14 | E18: =SUMIFS('Stock Guide'!M:M,'Stock Guide'!$G:$G,Segmentos!$B18) -> 3.9165443e+08 | F18: =SUMIFS('Stock Guide'!N:N,'Stock Guide'!$G:$G,Segmentos!$B18) -> 4.2811527e+08 | G18: =AVERAGEIFS('Stock Guide'!O:O,'Stock Guide'!$G:$G,Segmentos!$B18) -> 0.91483406 | H18: =AVERAGEIFS('Stock Guide'!P:P,'Stock Guide'!$G:$G,Segmentos!$B18) -> 0.98994817 | I18: =AVERAGEIFS('Stock Guide'!Q:Q,'Stock Guide'!$G:$G,Segmentos!$B18) -> 0.12661308 | J18: =AVERAGEIFS('Stock Guide'!R:R,'Stock Guide'!$G:$G,Segmentos!$B18) -> 0.10618686 | K18: =AVERAGEIFS('Stock Guide'!U:U,'Stock Guide'!$G:$G,Segmentos!$B18) -> -0.022066777 | L18: =AVERAGEIFS('Stock Guide'!V:V,'Stock Guide'!$G:$G,Segmentos!$B18) -> -0.024129605 | M18: =AVERAGEIFS('Stock Guide'!W:W,'Stock Guide'!$G:$G,Segmentos!$B18) -> 0.10230253
... B22: Residencial | C22: =SUMIFS('Stock Guide'!H:H,'Stock Guide'!$G:$G,Segmentos!$B22) -> 0 | D22: =AVERAGEIFS('Stock Guide'!I:I,'Stock Guide'!$G:$G,Segmentos!$B22) -> 90714.567 | E22: =SUMIFS('Stock Guide'!M:M,'Stock Guide'!$G:$G,Segmentos!$B22) -> 2.7509447e+08 | F22: =SUMIFS('Stock Guide'!N:N,'Stock Guide'!$G:$G,Segmentos!$B22) -> 4.9808968e+08 | G22: =AVERAGEIFS('Stock Guide'!O:O,'Stock Guide'!$G:$G,Segmentos!$B22) -> 0.55623795 | H22: =AVERAGEIFS('Stock Guide'!P:P,'Stock Guide'!$G:$G,Segmentos!$B22) -> 0.63688044 | I22: =AVERAGEIFS('Stock Guide'!Q:Q,'Stock Guide'!$G:$G,Segmentos!$B22) -> 0.098142503 | J22: =AVERAGEIFS('Stock Guide'!R:R,'Stock Guide'!$G:$G,Segmentos!$B22) -> 0.10101128 | K22: =AVERAGEIFS('Stock Guide'!U:U,'Stock Guide'!$G:$G,Segmentos!$B22) -> 0.0066340762 | L22: =AVERAGEIFS('Stock Guide'!V:V,'Stock Guide'!$G:$G,Segmentos!$B22) -> -0.089378632 | M22: =AVERAGEIFS('Stock Guide'!W:W,'Stock Guide'!$G:$G,Segmentos!$B22) -> 0.056502603
B26: Valor mercado vs. valor patrimonial
O33: 0.82328219 | P33: 0.079246247 | Q33: 0.084151473 | R33: 0.5 | S33: 0.12391618 | T33: -0.13692794 | U33: -0.12808499
O34: 0 | P34: 0 | Q34: 0.097759674 | R34: 0.8 | S34: 0.11270063 | T34: 0 | U34: 0
O35: 0.92755848 | P35: 0.091495288 | Q35: 0.11732754 | R35: 0.9 | S35: 0.042382454 | T35: 0.12046971 | U35: 0.14919643
O36: 1.103278 | P36: 0.078065134 | Q36: 0.082758621 | R36: 0.72 | S36: 0.043781926 | T36: 0.019388846 | U36: 0.024442149
O37: 0 | P37: 0 | Q37: 0.11134021 | R37: 0.9 | S37: 0.084377326 | T37: 0 | U37: 0
O38: 1.0511327 | P38: 0.12857143 | Q38: 0.16808905 | R38: 1.51 | S38: 0.059043128 | T38: 0.12845688 | U38: 0.17104016
O39: 0.94280494 | P39: 0.12593323 | Q39: 0.077757431 | R39: 0.46 | S39: 0.035597671 | T39: -0.026943965 | U39: -0.0086991639
O40: 1.1049199 | P40: 0.12795755 | Q40: 0.12607691 | R40: 1 | S40: 0.0037770818 | T40: 0.054595403 | U40: 0.069901726
O41: 1.0498016 | P41: 0.13482701 | Q41: 0.1332408 | R41: 1.12 | S41: 0.043062699 | T41: 0.12211911 | U41: 0.14615905
O42: 1.2726899 | P42: 0.22280393 | Q42: 0.099260991 | R42: 0.36139273 | S42: 0.11714538 | T42: -0.52214659 | U42: -0.52214659
O43: 0 | P43: 0 | Q43: 0.098222778 | R43: 0.654 | S43: 0.12304276 | T43: 0 | U43: 0
O44: 1.1831857 | P44: 0.17704066 | Q44: 0.17024678 | R44: 1.42 | S44: 0.033880712 | T44: 0.20443913 | U44: 0.17525449
... O48: 0.96608126 | P48: 0.10882708 | Q48: 0.12844677 | R48: 0.92 | S48: 0.076252982 | T48: 0.0051450133 | U48: 0.049476737
B49: Distribuição P/VPA | O49: 0.69642606 | P49: 0.054506968 | Q49: 0.067736814 | R49: 0.32 | S49: 0.15153362 | T49: -0.097975206 | U49: -0.10808004
O50: 1.2070211 | P50: 0.084629279 | Q50: 0.088814485 | R50: 3.36 | S50: 0.049325074 | T50: -0.086653132 | U50: -0.10694567
O51: 1.0320729 | P51: 0.089789659 | Q51: 0.095110352 | R51: 1.3 | S51: 0.033522369 | T51: -0.11335261 | U51: -0.11912264
O52: 0 | P52: 0 | Q52: 0.18897638 | R52: 1.6 | S52: 0.032848121 | T52: 0 | U52: 0
O53: 0 | P53: 0 | Q53: 0.10106276 | R53: 0.84 | S53: 0.0062550444 | T53: 0 | U53: 0
O54: 0 | P54: 0 | Q54: 0.13752174 | R54: 1.12 | S54: 0.020692054 | T54: 0 | U54: 0
O55: 1.1248562 | P55: 0.083811084 | Q55: 0.087360087 | R55: 0.8 | S55: 0.053927902 | T55: -0.15077375 | U55: -0.12836015
O56: 0.2514411 | P56: 0 | Q56: 0.0076239854 | R56: 0.002789108 | S56: 0.052757794 | T56: 0.25787966 | U56: 0.31437126
O57: 1.1003671 | P57: 0.098479902 | Q57: 0.09804878 | R57: 0.67 | S57: 0.14926419 | T57: -0.20209936 | U57: -0.20059659
...

Sheet Simulador de Carteiras (%)
Q2: Menu | R2: Stock Guide
B5: Simulação de Carteira
B6: Montante | D6: 1000000
B7: Fundo | C7: Peso | D7: Financeiro | E7: Cotas | F7: Características | H7: Preço | I7: Liquidez | J7: P/VPA | K7: Dividend Yield | N7: Dividendos¹ | P7: Performance
B8: Ticker | C8: (%) | D8: R$ | E8: Qtde. | F8: Nome do Fundo | G8: Segmento | H8: R$/Cota | I8: Média (R$ milhares 3M) | J8: - | K8: Mês (%) | L8: 12M (%) | M8: Anualizado (%) | N8: R$/Cota | O8: Montante | P8: 1M (%) | Q8: No ano (%) | R8: LTM (%)
B9: BTCI11 | C9: 0.06 | D9: =IF(C9*$D$6=0,"",C9*$D$6) -> 60000 | E9: =IFERROR(ROUNDDOWN(D9/H9,0),"") -> 6666 | F9: =IFERROR(VLOOKUP($B9,'Stock Guide'!$B:$W,3,0),"") -> BTG Pactual Crédito Imobiliário FII | G9: =IFERROR(VLOOKUP($B9,'Stock Guide'!$B:$W,6,0),"") -> Recebível | H9: =IFERROR(VLOOKUP($B9,'Stock Guide'!$B:$W,9,0),"") -> 9 | I9: =IFERROR(VLOOKUP($B9,'Stock Guide'!$B:$W,8,0)/1000,"") -> 3504.8616 | J9: =IFERROR(VLOOKUP($B9,'Stock Guide'!$B:$W,14,0),"") -> 0.89215724 | K9: =IFERROR(N9/H9,"") -> 0.011444444 | L9: =IFERROR(VLOOKUP($B9,'Stock Guide'!$B:$W,16,0),"") -> 0.13055556 | M9: =IFERROR((N9/H9)*12,"") -> 0.13733333 | N9: =IFERROR(VLOOKUP($B9,'Stock Guide'!$B:$W,19,0),"") -> 0.103 | O9: =IFERROR(N9*E9,"") -> 686.598 | P9: =IFERROR(VLOOKUP($B9,'Stock Guide'!$B:$W,20,0),"") -> -0.0040443824 | Q9: =IFERROR(VLOOKUP($B9,'Stock Guide'!$B:$W,21,0),"") -> 0.048974723 | R9: =IFERROR(VLOOKUP($B9,'Stock Guide'!$B:$W,22,0),"") -> 0.12285468
